elasticsearch - WARNING - GET http://localhost:9200/ [status:N/A request:2.014s]
Traceback (most recent call last):
  File "C:\Users\Hachem\Anaconda3\lib\site-packages\urllib3\connection.py", line 175, in _new_conn
    (self._dns_host, self.port), self.timeout, **extra_kw
  File "C:\Users\Hachem\Anaconda3\lib\site-packages\urllib3\util\connection.py", line 95, in create_connection
    raise err
  File "C:\Users\Hachem\Anaconda3\lib\site-packages\urllib3\util\connection.py", line 85, in create_connection
    sock.connect(sa)
ConnectionRefusedError: [WinError 10061] Aucune connexion n’a pu être établie car l’ordinateur cible l’a expressément refusée

During handling of the above exception, another exception occurred:

Traceback (most recent call last):
  File "C:\Users\Hachem\Anaconda3\lib\site-packages\elasticsearch\connection\http_urllib3.py", line 256, in perform_request
    method, url, body, retries=Retry(False), headers=request_headers, **kw
  File "C:\Users\Hachem\Anaconda3\lib\site-packages\urllib3\connectionpool.py", line 786, in urlopen
    method, url, error=e, _pool=self, _stacktrace=sys.exc_info()[2]
  File "C:\Users\Hachem\Anaconda3\lib\site-packages\urllib3\util\retry.py", line 525, in increment
    raise six.reraise(type(error), error, _stacktrace)
  File "C:\Users\Hachem\Anaconda3\lib\site-packages\urllib3\packages\six.py", line 770, in reraise
    raise value
  File "C:\Users\Hachem\Anaconda3\lib\site-packages\urllib3\connectionpool.py", line 710, in urlopen
    chunked=chunked,
  File "C:\Users\Hachem\Anaconda3\lib\site-packages\urllib3\connectionpool.py", line 398, in _make_request
    conn.request(method, url, **httplib_request_kw)
  File "C:\Users\Hachem\Anaconda3\lib\site-packages\urllib3\connection.py", line 239, in request
    super(HTTPConnection, self).request(method, url, body=body, headers=headers)
  File "C:\Users\Hachem\Anaconda3\lib\http\client.py", line 1229, in request
    self._send_request(method, url, body, headers, encode_chunked)
  File "C:\Users\Hachem\Anaconda3\lib\http\client.py", line 1275, in _send_request
    self.endheaders(body, encode_chunked=encode_chunked)
  File "C:\Users\Hachem\Anaconda3\lib\http\client.py", line 1224, in endheaders
    self._send_output(message_body, encode_chunked=encode_chunked)
  File "C:\Users\Hachem\Anaconda3\lib\http\client.py", line 1016, in _send_output
    self.send(msg)
  File "C:\Users\Hachem\Anaconda3\lib\http\client.py", line 956, in send
    self.connect()
  File "C:\Users\Hachem\Anaconda3\lib\site-packages\urllib3\connection.py", line 205, in connect
    conn = self._new_conn()
  File "C:\Users\Hachem\Anaconda3\lib\site-packages\urllib3\connection.py", line 187, in _new_conn
    self, "Failed to establish a new connection: %s" % e
urllib3.exceptions.NewConnectionError: <urllib3.connection.HTTPConnection object at 0x0000003E7A2E22B0>: Failed to establish a new connection: [WinError 10061] Aucune connexion n’a pu être établie car l’ordinateur cible l’a expressément refusée
